<mujoco model="lite3">
  <option iterations="50" timestep="0.001" solver="PGS" gravity="0 0 -9.81" />

  <compiler angle="radian" meshdir="meshes" eulerseq="zyx" autolimits="true" />

  <default>
    <joint limited="true" damping="0.01" armature="0.01" frictionloss="0.01" />
    <geom condim="4" contype="1" conaffinity="15" friction="0.9 0.2 0.2" solref="0.001 2" />
    <motor ctrllimited="true" />
    <equality solref="0.001 2" />
    <default class="visualgeom">
      <geom material="visualgeom" condim="1" contype="0" conaffinity="0" />
    </default>
  </default>

  <worldbody>
    <light directional="true" diffuse="0.4 0.4 0.4" specular="0.1 0.1 0.1" pos="0 0 5.0" dir="0 0 -1" castshadow="false" />
    <light directional="true" diffuse="0.6 0.6 0.6" specular="0.2 0.2 0.2" pos="0 0 4" dir="0 0 -1" />
    <geom name="ground" type="plane" pos="0 0 0" size="100 100 0.001" quat="1 0 0 0" material="matplane" condim="3" conaffinity="15" />
    <camera name="fixed" pos="0 -3.0 0.91" xyaxes="1 0 0 0 0 1" />
    <camera name="track" mode="trackcom" pos="0 -3.0 0.91" xyaxes="1 0 0 0 0 1" />
    <body name="root" pos="0 0 0.41000000000000003" quat="1 0 0 0">
      <freejoint name="root" />
      <site name="imu" size="0.01" pos="0 0 0" />
      <geom size="0.175 0.092 0.04" type="box" contype="1" conaffinity="0" density="0" group="1" class="visualgeom" />
      <geom type="box" rgba="" size="0.175 0.092 0.04" />
      <geom size="0.0005 0.0005 0.0005" type="box" contype="1" conaffinity="0" density="0" group="1" class="visualgeom" />
      <geom type="box" rgba="" size="0.0005 0.0005 0.0005" />
      <body name="FL_HIP" pos="0.1745 0.062 0">
        <inertial pos="-0.0047 -0.0091 -0.0018" quat="0.684923 0.185524 0.176437 0.682152" mass="0.428" diaginertia="0.000240261 0.000152578 0.000123161" />
        <joint name="FL_HipX" pos="0 0 0" axis="-1 0 0" range="-0.42 0.42" actuatorfrcrange="-24 24" />
        <body name="FL_THIGH" pos="0 0.0985 0">
          <inertial pos="-0.00523 -0.0216 -0.0273" quat="0.698912 0.0529083 0.0519832 0.711351" mass="0.61" diaginertia="0.00116004 0.00101671 0.000251247" />
          <joint name="FL_HipY" pos="0 0 0" axis="0 -1 0" range="-2.67 0.314" actuatorfrcrange="-24 24" />
          <geom size="0.01 0.01 0.08" pos="0 0 -0.08" type="box" contype="1" conaffinity="0" density="0" group="1" class="visualgeom" />
          <geom type="box" rgba="" size="0.01 0.01 0.08" pos="0 0 -0.08" />
          <body name="FL_SHANK" pos="0 0 -0.2">
            <inertial pos="0.00585 -8.732e-07 -0.12" quat="0.706853 -0.00383613 -0.00383974 0.70734" mass="0.115" diaginertia="0.000686 0.000668075 3.1475e-05" />
            <joint name="FL_Knee" pos="0 0 0" axis="0 -1 0" range="0.6 2.72" actuatorfrcrange="-36 36" />
            <geom size="0.01 0.01 0.09" pos="0 0 -0.09" type="box" contype="1" conaffinity="0" density="0" group="1" class="visualgeom" />
            <geom type="box" rgba="" size="0.01 0.01 0.09" pos="0 0 -0.09" />
            <geom size="0.013" pos="0 0 -0.21" contype="1" conaffinity="0" density="0" group="1" class="visualgeom" />
            <geom type="" rgba="" pos="0 0 -0.21" />
          </body>
        </body>
      </body>
      <body name="FR_HIP" pos="0.1745 -0.062 0">
        <inertial pos="-0.0047 0.0091 -0.0018" quat="0.682155 0.176432 0.185517 0.684923" mass="0.428" diaginertia="0.000240261 0.000152577 0.000123162" />
        <joint name="FR_HipX" pos="0 0 0" axis="-1 0 0" range="-0.42 0.42" actuatorfrcrange="-24 24" />
        <body name="FR_THIGH" pos="0 -0.0985 0">
          <inertial pos="-0.00523 0.0216 -0.0273" quat="0.711351 0.0519832 0.0529083 0.698912" mass="0.61" diaginertia="0.00116004 0.00101671 0.000251247" />
          <joint name="FR_HipY" pos="0 0 0" axis="0 -1 0" range="-2.67 0.314" actuatorfrcrange="-24 24" />
          <geom size="0.01 0.01 0.08" pos="0 0 -0.08" type="box" contype="1" conaffinity="0" density="0" group="1" class="visualgeom" />
          <geom type="box" rgba="" size="0.01 0.01 0.08" pos="0 0 -0.08" />
          <body name="FR_SHANK" pos="0 0 -0.2">
            <inertial pos="0.00585 -8.732e-07 -0.12" quat="0.706853 -0.00383613 -0.00383974 0.70734" mass="0.115" diaginertia="0.000686 0.000668075 3.1475e-05" />
            <joint name="FR_Knee" pos="0 0 0" axis="0 -1 0" range="0.6 2.72" actuatorfrcrange="-36 36" />
            <geom size="0.01 0.01 0.09" pos="0 0 -0.09" type="box" contype="1" conaffinity="0" density="0" group="1" class="visualgeom" />
            <geom type="box" rgba="" size="0.01 0.01 0.09" pos="0 0 -0.09" />
            <geom size="0.013" pos="0 0 -0.21" contype="1" conaffinity="0" density="0" group="1" class="visualgeom" />
            <geom type="" rgba="" pos="0 0 -0.21" />
          </body>
        </body>
      </body>
      <body name="HL_HIP" pos="-0.1745 0.062 0">
        <inertial pos="0.0047 -0.0091 -0.0018" quat="0.682154 -0.176431 -0.185518 0.684924" mass="0.428" diaginertia="0.000240261 0.000152577 0.000123162" />
        <joint name="HL_HipX" pos="0 0 0" axis="-1 0 0" range="-0.42 0.42" actuatorfrcrange="-24 24" />
        <body name="HL_THIGH" pos="0 0.0985 0">
          <inertial pos="-0.00523 -0.0216 -0.0273" quat="0.698912 0.0529083 0.0519832 0.711351" mass="0.61" diaginertia="0.00116004 0.00101671 0.000251247" />
          <joint name="HL_HipY" pos="0 0 0" axis="0 -1 0" range="-2.67 0.314" actuatorfrcrange="-24 24" />
          <geom size="0.01 0.01 0.08" pos="0 0 -0.08" type="box" contype="1" conaffinity="0" density="0" group="1" class="visualgeom" />
          <geom type="box" rgba="" size="0.01 0.01 0.08" pos="0 0 -0.08" />
          <body name="HL_SHANK" pos="0 0 -0.2">
            <inertial pos="0.00585 -8.732e-07 -0.12" quat="0.706853 -0.00383613 -0.00383974 0.70734" mass="0.115" diaginertia="0.000686 0.000668075 3.1475e-05" />
            <joint name="HL_Knee" pos="0 0 0" axis="0 -1 0" range="0.6 2.72" actuatorfrcrange="-36 36" />
            <geom size="0.01 0.01 0.09" pos="0 0 -0.09" type="box" contype="1" conaffinity="0" density="0" group="1" class="visualgeom" />
            <geom type="box" rgba="" size="0.01 0.01 0.09" pos="0 0 -0.09" />
            <geom size="0.013" pos="0 0 -0.21" contype="1" conaffinity="0" density="0" group="1" class="visualgeom" />
            <geom type="" rgba="" pos="0 0 -0.21" />
          </body>
        </body>
      </body>
      <body name="HR_HIP" pos="-0.1745 -0.062 0">
        <inertial pos="0.0047 0.0091 -0.0018" quat="0.684923 -0.185517 -0.176432 0.682155" mass="0.428" diaginertia="0.000240261 0.000152577 0.000123162" />
        <joint name="HR_HipX" pos="0 0 0" axis="-1 0 0" range="-0.42 0.42" actuatorfrcrange="-24 24" />
        <body name="HR_THIGH" pos="0 -0.0985 0">
          <inertial pos="-0.00523 0.0216 -0.0273" quat="0.711351 0.0519832 0.0529083 0.698912" mass="0.61" diaginertia="0.00116004 0.00101671 0.000251247" />
          <joint name="HR_HipY" pos="0 0 0" axis="0 -1 0" range="-2.67 0.314" actuatorfrcrange="-24 24" />
          <geom size="0.01 0.01 0.08" pos="0 0 -0.08" type="box" contype="1" conaffinity="0" density="0" group="1" class="visualgeom" />
          <geom type="box" rgba="" size="0.01 0.01 0.08" pos="0 0 -0.08" />
          <body name="HR_SHANK" pos="0 0 -0.2">
            <inertial pos="0.00585 -8.732e-07 -0.12" quat="0.706853 -0.00383613 -0.00383974 0.70734" mass="0.115" diaginertia="0.000686 0.000668075 3.1475e-05" />
            <joint name="HR_Knee" pos="0 0 0" axis="0 -1 0" range="0.6 2.72" actuatorfrcrange="-36 36" />
            <geom size="0.01 0.01 0.09" pos="0 0 -0.09" type="box" contype="1" conaffinity="0" density="0" group="1" class="visualgeom" />
            <geom type="box" rgba="" size="0.01 0.01 0.09" pos="0 0 -0.09" />
            <geom size="0.013" pos="0 0 -0.21" contype="1" conaffinity="0" density="0" group="1" class="visualgeom" />
            <geom type="" rgba="" pos="0 0 -0.21" />
          </body>
        </body>
      </body>
    </body>
  </worldbody>

  <asset>
    <texture name="texplane" type="2d" builtin="checker" rgb1=".0 .0 .0" rgb2=".8 .8 .8" width="100" height="100" />
    <material name="matplane" reflectance="0." texture="texplane" texrepeat="1 1" texuniform="true" />
    <material name="visualgeom" rgba="0.5 0.9 0.2 1" />
  </asset>

  <actuator>
    <motor name="FL_HipX" joint="FL_HipX" ctrllimited="true" ctrlrange="-24 24" gear="1" />
    <motor name="FL_HipY" joint="FL_HipY" ctrllimited="true" ctrlrange="-24 24" gear="1" />
    <motor name="FL_Knee" joint="FL_Knee" ctrllimited="true" ctrlrange="-36 36" gear="1" />
    <motor name="FR_HipX" joint="FR_HipX" ctrllimited="true" ctrlrange="-24 24" gear="1" />
    <motor name="FR_HipY" joint="FR_HipY" ctrllimited="true" ctrlrange="-24 24" gear="1" />
    <motor name="FR_Knee" joint="FR_Knee" ctrllimited="true" ctrlrange="-36 36" gear="1" />
    <motor name="HL_HipX" joint="HL_HipX" ctrllimited="true" ctrlrange="-24 24" gear="1" />
    <motor name="HL_HipY" joint="HL_HipY" ctrllimited="true" ctrlrange="-24 24" gear="1" />
    <motor name="HL_Knee" joint="HL_Knee" ctrllimited="true" ctrlrange="-36 36" gear="1" />
    <motor name="HR_HipX" joint="HR_HipX" ctrllimited="true" ctrlrange="-24 24" gear="1" />
    <motor name="HR_HipY" joint="HR_HipY" ctrllimited="true" ctrlrange="-24 24" gear="1" />
    <motor name="HR_Knee" joint="HR_Knee" ctrllimited="true" ctrlrange="-36 36" gear="1" />
  </actuator>

  <sensor>
    <actuatorpos name="FL_HipX_p" actuator="FL_HipX" />
    <actuatorvel name="FL_HipX_v" actuator="FL_HipX" />
    <actuatorfrc name="FL_HipX_f" actuator="FL_HipX" noise="0.001" />
    <actuatorpos name="FL_HipY_p" actuator="FL_HipY" />
    <actuatorvel name="FL_HipY_v" actuator="FL_HipY" />
    <actuatorfrc name="FL_HipY_f" actuator="FL_HipY" noise="0.001" />
    <actuatorpos name="FL_Knee_p" actuator="FL_Knee" />
    <actuatorvel name="FL_Knee_v" actuator="FL_Knee" />
    <actuatorfrc name="FL_Knee_f" actuator="FL_Knee" noise="0.001" />
    <actuatorpos name="FR_HipX_p" actuator="FR_HipX" />
    <actuatorvel name="FR_HipX_v" actuator="FR_HipX" />
    <actuatorfrc name="FR_HipX_f" actuator="FR_HipX" noise="0.001" />
    <actuatorpos name="FR_HipY_p" actuator="FR_HipY" />
    <actuatorvel name="FR_HipY_v" actuator="FR_HipY" />
    <actuatorfrc name="FR_HipY_f" actuator="FR_HipY" noise="0.001" />
    <actuatorpos name="FR_Knee_p" actuator="FR_Knee" />
    <actuatorvel name="FR_Knee_v" actuator="FR_Knee" />
    <actuatorfrc name="FR_Knee_f" actuator="FR_Knee" noise="0.001" />
    <actuatorpos name="HL_HipX_p" actuator="HL_HipX" />
    <actuatorvel name="HL_HipX_v" actuator="HL_HipX" />
    <actuatorfrc name="HL_HipX_f" actuator="HL_HipX" noise="0.001" />
    <actuatorpos name="HL_HipY_p" actuator="HL_HipY" />
    <actuatorvel name="HL_HipY_v" actuator="HL_HipY" />
    <actuatorfrc name="HL_HipY_f" actuator="HL_HipY" noise="0.001" />
    <actuatorpos name="HL_Knee_p" actuator="HL_Knee" />
    <actuatorvel name="HL_Knee_v" actuator="HL_Knee" />
    <actuatorfrc name="HL_Knee_f" actuator="HL_Knee" noise="0.001" />
    <actuatorpos name="HR_HipX_p" actuator="HR_HipX" />
    <actuatorvel name="HR_HipX_v" actuator="HR_HipX" />
    <actuatorfrc name="HR_HipX_f" actuator="HR_HipX" noise="0.001" />
    <actuatorpos name="HR_HipY_p" actuator="HR_HipY" />
    <actuatorvel name="HR_HipY_v" actuator="HR_HipY" />
    <actuatorfrc name="HR_HipY_f" actuator="HR_HipY" noise="0.001" />
    <actuatorpos name="HR_Knee_p" actuator="HR_Knee" />
    <actuatorvel name="HR_Knee_v" actuator="HR_Knee" />
    <actuatorfrc name="HR_Knee_f" actuator="HR_Knee" noise="0.001" />
    <framequat name="orientation" objtype="site" noise="0.001" objname="imu" />
    <gyro name="angular-velocity" site="imu" noise="0.005" cutoff="34.9" />
  </sensor>
</mujoco>